<?xml version="1.0"?>
<robot name="aron" xmlns:xacro="http://ros.org/wiki/xacro">

  <xacro:arg name="robot_name" default="aron"/>
  <xacro:arg name="base_link_frame" default="base_link"/>
  <xacro:arg name="use_world_frame" default="false"/>

  <material name="black">
    <color rgba="0.2 0.2 0.2 1.0"/>
  </material>
  
  <material name="white">
    <color rgba="1.0 1.0 1.0 1.0"/>
  </material>

  <xacro:if value="$(arg use_world_frame)">
    <link name="world"/>
    <joint name="fixed" type="fixed">
      <parent link="world"/>
      <child link="$(arg robot_name)/$(arg base_link_frame)"/>
    </joint>
  </xacro:if>

  <link name="$(arg robot_name)/$(arg base_link_frame)">
    <visual>
      <origin rpy="0 0 0" xyz="0 0 0"/>
      <geometry>
        <mesh filename="package://aron_description/meshes/XL-430_Pan.stl" scale="0.001 0.001 0.001"/>
      </geometry>
      <material name="black"/>
    </visual>
  </link>

  <link name="$(arg robot_name)/neck_link">
    <visual>
      <origin rpy="0 0 0" xyz="0 0.0228 -0.2365"/>
      <geometry>
        <mesh filename="package://aron_description/meshes/Neck.stl" scale="0.001 0.001 0.001"/>
      </geometry>
      <material name="white"/>
    </visual>
  </link>

  <joint name="pan" type="revolute">
    <axis xyz="0 0 1"/>
    <limit effort="3" lower="${radians(-90)}" upper="${radians(90)}" velocity="${pi}"/>
    <origin rpy="0 0 0" xyz="0 -0.0228 0.2365"/>
    <parent link="$(arg robot_name)/base_link"/>
    <child link="$(arg robot_name)/neck_link"/>
  </joint>

  <link name="$(arg robot_name)/tilt_link">
    <visual>
      <origin rpy="0 0 0" xyz="0 0.0228 -0.2757"/>	
      <geometry>
        <mesh filename="package://aron_description/meshes/XL-430_Tilt.stl" scale="0.001 0.001 0.001"/>
      </geometry>
      <material name="black"/>
    </visual>
  </link>

  <joint name="tilt" type="revolute">
    <axis xyz="1 0 0"/>
    <limit effort="3" lower="${radians(-12)}" upper="${radians(47)}" velocity="${pi}"/>
    <origin rpy="0 0 0" xyz="0 0 0.0392"/>
    <parent link="$(arg robot_name)/neck_link"/>
    <child link="$(arg robot_name)/tilt_link"/>
  </joint>

</robot>
